Workbook

Sheet Orders Dataset
A1: Order ID | B1: Order Date | C1: CustomerName | D1: State | E1: City | F1: Month | G1: Year
A2: B-26055 | B2: 43169 | C2: Harivansh | D2: Uttar Pradesh | E2: Mathura | F2: =MONTH(B2) -> 3 | G2: =YEAR(B2) -> 2018
A3: B-25993 | B3: 43134 | C3: Madhav | D3: Delhi | E3: Delhi | F3: =MONTH(B3) -> 2 | G3: =YEAR(B3) -> 2018
A4: B-25973 | B4: 43124 | C4: Madan Mohan | D4: Uttar Pradesh | E4: Mathura | F4: =MONTH(B4) -> 1 | G4: =YEAR(B4) -> 2018
A5: B-25923 | B5: 43461 | C5: Gopal | D5: Maharashtra | E5: Mumbai | F5: =MONTH(B5) -> 12 | G5: =YEAR(B5) -> 2018
A6: B-25757 | B6: 43333 | C6: Vishakha | D6: Madhya Pradesh | E6: Indore | F6: =MONTH(B6) -> 8 | G6: =YEAR(B6) -> 2018
A7: B-25967 | B7: 43121 | C7: Sudevi | D7: Uttar Pradesh | E7: Prayagraj | F7: =MONTH(B7) -> 1 | G7: =YEAR(B7) -> 2018
A8: B-25955 | B8: 43116 | C8: Shiva | D8: Maharashtra | E8: Pune | F8: =MONTH(B8) -> 1 | G8: =YEAR(B8) -> 2018
A9: B-26093 | B9: 43186 | C9: Sarita | D9: Maharashtra | E9: Pune | F9: =MONTH(B9) -> 3 | G9: =YEAR(B9) -> 2018
A10: B-25798 | B10: 43374 | C10: Shishu | D10: Andhra Pradesh | E10: Hyderabad | F10: =MONTH(B10) -> 10 | G10: =YEAR(B10) -> 2018
A11: B-25602 | B11: 43191 | C11: Vrinda | D11: Maharashtra | E11: Pune | F11: =MONTH(B11) -> 4 | G11: =YEAR(B11) -> 2018
A12: B-25858 | B12: 43417 | C12: Uudhav | D12: Maharashtra | E12: Mumbai | F12: =MONTH(B12) -> 11 | G12: =YEAR(B12) -> 2018
A13: B-25969 | B13: 43121 | C13: Shreyshi | D13: Gujarat | E13: Surat | F13: =MONTH(B13) -> 1 | G13: =YEAR(B13) -> 2018
... A501: B-26095 | B501: 43187 | C501: Monisha | D501: Rajasthan | E501: Jaipur | F501: =MONTH(B501) -> 3 | G501: =YEAR(B501) -> 2018

Sheet Details Dataset
A1: Order ID | B1: Amount | C1: Profit | D1: Quantity | E1: Category | F1: Sub-Category | G1: PaymentMode | H1: State | I1: City
A2: B-25681 | B2: 1096 | C2: 658 | D2: 7 | E2: Electronics | F2: Electronic Games | G2: COD | H2: =VLOOKUP(A2,'Orders Dataset'!$A:$D,4,FALSE) -> Madhya Pradesh | I2: =VLOOKUP(A2,'Orders Dataset'!$A:$E,5,FALSE) -> Indore
A3: B-26055 | B3: 5729 | C3: 64 | D3: 14 | E3: Furniture | F3: Chairs | G3: EMI | H3: =VLOOKUP(A3,'Orders Dataset'!$A:$D,4,FALSE) -> Uttar Pradesh | I3: =VLOOKUP(A3,'Orders Dataset'!$A:$E,5,FALSE) -> Mathura
A4: B-25955 | B4: 2927 | C4: 146 | D4: 8 | E4: Furniture | F4: Bookcases | G4: EMI | H4: =VLOOKUP(A4,'Orders Dataset'!$A:$D,4,FALSE) -> Maharashtra | I4: =VLOOKUP(A4,'Orders Dataset'!$A:$E,5,FALSE) -> Pune
A5: B-26093 | B5: 2847 | C5: 712 | D5: 8 | E5: Electronics | F5: Printers | G5: Credit Card | H5: =VLOOKUP(A5,'Orders Dataset'!$A:$D,4,FALSE) -> Maharashtra | I5: =VLOOKUP(A5,'Orders Dataset'!$A:$E,5,FALSE) -> Pune
A6: B-25602 | B6: 2617 | C6: 1151 | D6: 4 | E6: Electronics | F6: Phones | G6: Credit Card | H6: =VLOOKUP(A6,'Orders Dataset'!$A:$D,4,FALSE) -> Maharashtra | I6: =VLOOKUP(A6,'Orders Dataset'!$A:$E,5,FALSE) -> Pune
A7: B-25881 | B7: 2244 | C7: 247 | D7: 4 | E7: Clothing | F7: Trousers | G7: Credit Card | H7: =VLOOKUP(A7,'Orders Dataset'!$A:$D,4,FALSE) -> Uttar Pradesh | I7: =VLOOKUP(A7,'Orders Dataset'!$A:$E,5,FALSE) -> Mathura
A8: B-25696 | B8: 275 | C8: -275 | D8: 4 | E8: Clothing | F8: Saree | G8: COD | H8: =VLOOKUP(A8,'Orders Dataset'!$A:$D,4,FALSE) -> Karnataka | I8: =VLOOKUP(A8,'Orders Dataset'!$A:$E,5,FALSE) -> Bangalore
A9: B-25687 | B9: 387 | C9: -213 | D9: 5 | E9: Clothing | F9: Saree | G9: UPI | H9: =VLOOKUP(A9,'Orders Dataset'!$A:$D,4,FALSE) -> Maharashtra | I9: =VLOOKUP(A9,'Orders Dataset'!$A:$E,5,FALSE) -> Mumbai
A10: B-25643 | B10: 50 | C10: -44 | D10: 2 | E10: Clothing | F10: Hankerchief | G10: UPI | H10: =VLOOKUP(A10,'Orders Dataset'!$A:$D,4,FALSE) -> Jammu and Kashmir | I10: =VLOOKUP(A10,'Orders Dataset'!$A:$E,5,FALSE) -> Kashmir
A11: B-25851 | B11: 135 | C11: -54 | D11: 5 | E11: Clothing | F11: Kurti | G11: COD | H11: =VLOOKUP(A11,'Orders Dataset'!$A:$D,4,FALSE) -> Nagaland | I11: =VLOOKUP(A11,'Orders Dataset'!$A:$E,5,FALSE) -> Kohima
A12: B-25703 | B12: 231 | C12: -190 | D12: 9 | E12: Clothing | F12: Hankerchief | G12: COD | H12: =VLOOKUP(A12,'Orders Dataset'!$A:$D,4,FALSE) -> Madhya Pradesh | I12: =VLOOKUP(A12,'Orders Dataset'!$A:$E,5,FALSE) -> Indore
A13: B-25887 | B13: 2125 | C13: -234 | D13: 6 | E13: Electronics | F13: Printers | G13: EMI | H13: =VLOOKUP(A13,'Orders Dataset'!$A:$D,4,FALSE) -> Uttar Pradesh | I13: =VLOOKUP(A13,'Orders Dataset'!$A:$E,5,FALSE) -> Prayagraj
... A1501: B-25993 | B1501: 4363 | C1501: 305 | D1501: 5 | E1501: Furniture | F1501: Tables | G1501: EMI | H1501: =VLOOKUP(A1501,'Orders Dataset'!$A:$D,4,FALSE) -> Delhi | I1501: =VLOOKUP(A1501,'Orders Dataset'!$A:$E,5,FALSE) -> Delhi

Sheet Task-1
A1: Amount | B1: Profit
A2: 1096 | B2: 658 | D2: Correlation Coefficient
A3: 5729 | B3: 64 | D3: =CORREL(A1:A1501,B1:B1501) -> 0.30924224 | E3: <<<<< | F3: Moderate Positive Relationship
A4: 2927 | B4: 146
A5: 2847 | B5: 712 | D5: Outlier close to ( -2000)
A6: 2617 | B6: 1151
A7: 2244 | B7: 247
A8: 275 | B8: -275
A9: 387 | B9: -213
A10: 50 | B10: -44
A11: 135 | B11: -54
A12: 231 | B12: -190
A13: 2125 | B13: -234
A14: 3873 | B14: -891
A15: 729 | B15: -492
A16: 2188 | B16: 1050
A17: 6 | B17: -3
... A1501: 4363 | B1501: 305

Sheet Task-2
A1: Order ID | B1: Amount | C1: Profit | D1: Quantity | E1: Category | F1: Sub-Category | G1: PaymentMode | I1: Electronics | J1: Furniture | K1: Clothing | N1: Electronics | O1: Furniture | P1: Clothing | R1: Electronics | S1: Furniture | T1: Clothing
A2: B-25681 | B2: 1096 | C2: 658 | D2: 7 | E2: Electronics | F2: Electronic Games | G2: COD | I2: {=_xlfn._xlws.FILTER($C$2:$C$1501,$E$2:$E$1501="Electronics")} -> 658 | J2: {=_xlfn._xlws.FILTER($C$2:$C$1501,$E$2:$E$1501="Furniture")} -> 64 | K2: {=_xlfn._xlws.FILTER($C$2:$C$1501,$E$2:$E$1501="Clothing")} -> 247 | M2: Mean | N2: =AVERAGE(_xlfn.ANCHORARRAY(I2)) -> 42.733766 | O2: =AVERAGE(_xlfn.ANCHORARRAY(J2)) -> 43.111111 | P2: =AVERAGE(_xlfn.ANCHORARRAY(K2)) -> 14.041096 | R2: =_xlfn.QUARTILE.INC(_xlfn.ANCHORARRAY(I2),1) -> -41 | S2: =_xlfn.QUARTILE.INC(_xlfn.ANCHORARRAY(J2),1) -> -36 | T2: =_xlfn.QUARTILE.INC(_xlfn.ANCHORARRAY(K2),1) -> -5 | U2: Q1
A3: B-26055 | B3: 5729 | C3: 64 | D3: 14 | E3: Furniture | F3: Chairs | G3: EMI | I3: 712 | J3: 146 | K3: -275 | M3: Median | N3: =MEDIAN(_xlfn.ANCHORARRAY(I2)) -> 18 | O3: =MEDIAN(_xlfn.ANCHORARRAY(J2)) -> 13 | P3: =MEDIAN(_xlfn.ANCHORARRAY(K2)) -> 6 | R3: =_xlfn.QUARTILE.INC(_xlfn.ANCHORARRAY(I2),3) -> 101.25 | S3: =_xlfn.QUARTILE.INC(_xlfn.ANCHORARRAY(J2),3) -> 86.5 | T3: =_xlfn.QUARTILE.INC(_xlfn.ANCHORARRAY(K2),3) -> 23 | U3: Q3
A4: B-25955 | B4: 2927 | C4: 146 | D4: 8 | E4: Furniture | F4: Bookcases | G4: EMI | I4: 1151 | J4: -492 | K4: -213 | R4: =R3-R2 -> 142.25 | S4: =S3-S2 -> 122.5 | T4: =T3-T2 -> 28 | U4: IQR
A5: B-26093 | B5: 2847 | C5: 712 | D5: 8 | E5: Electronics | F5: Printers | G5: Credit Card | I5: -234 | J5: 1050 | K5: -44 | M5: Electronics Orders has higher profit than typical Furniture order
A6: B-25602 | B6: 2617 | C6: 1151 | D6: 4 | E6: Electronics | F6: Phones | G6: Credit Card | I6: -891 | J6: 433 | K6: -54
A7: B-25881 | B7: 2244 | C7: 247 | D7: 4 | E7: Clothing | F7: Trousers | G7: Credit Card | I7: 95 | J7: 721 | K7: -190
A8: B-25696 | B8: 275 | C8: -275 | D8: 4 | E8: Clothing | F8: Saree | G8: COD | I8: 254 | J8: -624 | K8: -3
A9: B-25687 | B9: 387 | C9: -213 | D9: 5 | E9: Clothing | F9: Saree | G9: UPI | I9: 782 | J9: -56 | K9: 1
A10: B-25643 | B10: 50 | C10: -44 | D10: 2 | E10: Clothing | F10: Hankerchief | G10: UPI | I10: 370 | J10: 202 | K10: -1
A11: B-25851 | B11: 135 | C11: -54 | D11: 5 | E11: Clothing | F11: Kurti | G11: COD | I11: -266 | J11: 122 | K11: -33
A12: B-25703 | B12: 231 | C12: -190 | D12: 9 | E12: Clothing | F12: Hankerchief | G12: COD | I12: 1303 | J12: 802 | K12: 2
A13: B-25887 | B13: 2125 | C13: -234 | D13: 6 | E13: Electronics | F13: Printers | G13: EMI | I13: -212 | J13: 980 | K13: -1
A14: B-25923 | B14: 3873 | C14: -891 | D14: 6 | E14: Electronics | F14: Phones | G14: Credit Card | I14: -77 | J14: 460 | K14: 113
A15: B-25756 | B15: 729 | C15: -492 | D15: 5 | E15: Furniture | F15: Bookcases | G15: UPI | I15: -448 | J15: 206 | K15: -15
A16: B-25761 | B16: 2188 | C16: 1050 | D16: 5 | E16: Furniture | F16: Bookcases | G16: Credit Card | I16: 340 | J16: 1864 | K16: -1
A17: B-25655 | B17: 6 | C17: -3 | D17: 1 | E17: Clothing | F17: Hankerchief | G17: UPI | I17: -439 | J17: 342 | K17: 0
... A244: B-25656 | B244: 30 | C244: -5 | D244: 5 | E244: Clothing | F244: Stole | G244: UPI | I244: 5 | J244: 305 | K244: 3
A245: B-26067 | B245: 618 | C245: 27 | D245: 4 | E245: Furniture | F245: Bookcases | G245: Credit Card | I245: 81 | K245: 62
A246: B-25673 | B246: 143 | C246: -124 | D246: 5 | E246: Clothing | F246: Saree | G246: UPI | I246: -43 | K246: 24
A247: B-25797 | B247: 31 | C247: 1 | D247: 2 | E247: Clothing | F247: Hankerchief | G247: UPI | I247: 215 | K247: -31
A248: B-26098 | B248: 409 | C248: 86 | D248: 3 | E248: Clothing | F248: Saree | G248: COD | I248: -174 | K248: 52
A249: B-25656 | B249: 406 | C249: 126 | D249: 2 | E249: Clothing | F249: Saree | G249: COD | I249: 26 | K249: 2
A250: B-25791 | B250: 565 | C250: 66 | D250: 7 | E250: Clothing | F250: Saree | G250: Credit Card | I250: 139 | K250: 27
A251: B-26053 | B251: 85 | C251: 2 | D251: 6 | E251: Clothing | F251: Stole | G251: COD | I251: 92 | K251: 111
A252: B-25983 | B252: 561 | C252: 118 | D252: 5 | E252: Furniture | F252: Bookcases | G252: Credit Card | I252: -102 | K252: 2
A253: B-25743 | B253: 503 | C253: -56 | D253: 2 | E253: Clothing | F253: Trousers | G253: COD | I253: 37 | K253: -12
A254: B-25867 | B254: 31 | C254: 14 | D254: 3 | E254: Clothing | F254: Stole | G254: UPI | I254: -444 | K254: -25
A255: B-25973 | B255: 398 | C255: 111 | D255: 8 | E255: Clothing | F255: Hankerchief | G255: COD | I255: -204 | K255: 2
A256: B-25895 | B256: 388 | C256: 93 | D256: 2 | E256: Furniture | F256: Bookcases | G256: COD | I256: 212 | K256: -206
... A309: B-25770 | B309: 299 | C309: 113 | D309: 2 | E309: Furniture | F309: Bookcases | G309: COD | I309: 1698 | K309: 153
A310: B-25840 | B310: 298 | C310: 74 | D310: 2 | E310: Furniture | F310: Bookcases | G310: COD | K310: 0
A311: B-25846 | B311: 94 | C311: 7 | D311: 7 | E311: Clothing | F311: Leggings | G311: UPI | K311: 0
A312: B-25745 | B312: 296 | C312: 225 | D312: 11 | E312: Clothing | F312: Saree | G312: COD | K312: 23
A313: B-26073 | B313: 37 | C313: 17 | D313: 3 | E313: Clothing | F313: Hankerchief | G313: Debit Card | K313: 54
A314: B-26030 | B314: 291 | C314: 93 | D314: 2 | E314: Electronics | F314: Printers | G314: COD | K314: 15
A315: B-25678 | B315: 327 | C315: -39 | D315: 1 | E315: Electronics | F315: Phones | G315: COD | K315: 51
A316: B-26035 | B316: 291 | C316: 119 | D316: 11 | E316: Clothing | F316: Saree | G316: COD | K316: -1
A317: B-25896 | B317: 287 | C317: -66 | D317: 6 | E317: Clothing | F317: Kurti | G317: COD | K317: 22
A318: B-25989 | B318: 42 | C318: 15 | D318: 1 | E318: Electronics | F318: Accessories | G318: UPI | K318: 50
...

Sheet Task-3
B2: Count of Order ID | C2: PaymentMode
B3: State | C3: COD | D3: Credit Card | E3: Debit Card | F3: EMI | G3: UPI | H3: Grand Total
B4: Andhra Pradesh | C4: 15 | D4: 8 | E4: 5 | F4: 6 | G4: 8 | H4: 42 | O4: Maximum UPI mode use in Madhya Pradesh
B5: Bihar | C5: 23 | D5: 4 | E5: 15 | F5: 6 | G5: 14 | H5: 62 | O5: Minimum UPI mode use in sikkim
B6: Delhi | C6: 37 | D6: 8 | E6: 9 | F6: 5 | G6: 17 | H6: 76
B7: Goa | C7: 25 | D7: 4 | E7: 4 | F7: 1 | G7: 9 | H7: 43
B8: Gujarat | C8: 33 | D8: 9 | E8: 13 | F8: 7 | G8: 25 | H8: 87
B9: Haryana | C9: 11 | D9: 2 | E9: 5 | F9: 1 | G9: 7 | H9: 26
B10: Himachal Pradesh | C10: 17 | D10: 4 | E10: 3 | F10: 3 | G10: 2 | H10: 29
B11: Jammu and Kashmir | C11: 23 | D11: 7 | E11: 10 | F11: 2 | G11: 7 | H11: 49
B12: Karnataka | C12: 21 | D12: 7 | E12: 4 | F12: 4 | G12: 14 | H12: 50
B13: Kerala | C13: 15 | D13: 8 | E13: 6 | F13: 4 | G13: 12 | H13: 45
B14: Madhya Pradesh | C14: 147 | D14: 34 | E14: 34 | F14: 24 | G14: 75 | H14: 314
B15: Maharashtra | C15: 145 | D15: 28 | E15: 41 | F15: 24 | G15: 61 | H15: 299
B16: Nagaland | C16: 17 | D16: 6 | E16: 5 | F16: 5 | G16: 12 | H16: 45
B17: Punjab | C17: 30 | D17: 4 | E17: 5 | F17: 7 | G17: 14 | H17: 60
B18: Rajasthan | C18: 32 | D18: 7 | E18: 14 | F18: 6 | G18: 15 | H18: 74
B19: Sikkim | C19: 6 | E19: 6 | F19: 2 | G19: 10 | H19: 24
B20: Tamil Nadu | C20: 13 | D20: 4 | E20: 3 | G20: 5 | H20: 25
B21: Uttar Pradesh | C21: 45 | D21: 12 | E21: 11 | F21: 6 | G21: 13 | H21: 87
B22: West Bengal | C22: 29 | D22: 7 | E22: 9 | F22: 7 | G22: 11 | H22: 63
B23: Grand Total | C23: 684 | D23: 163 | E23: 202 | F23: 120 | G23: 331 | H23: 1500

Sheet Task-4
A1: Profit | B1: Quantity
A2: 658 | B2: 7
A3: 64 | B3: 14
A4: 146 | B4: 8 | L4: Maximum | M4: =MAX(A2:A1501) -> 1864 | N4: < outlier
A5: 712 | B5: 8
A6: 1151 | B6: 4
A7: 247 | B7: 4
A8: -275 | B8: 4
A9: -213 | B9: 5
A10: -44 | B10: 2
A11: -54 | B11: 5
A12: -190 | B12: 9
A13: -234 | B13: 6
A14: -891 | B14: 6
A15: -492 | B15: 5
A16: 1050 | B16: 5
A17: -3 | B17: 1
A18: 433 | B18: 5 | D18: Correlation Coefficent
A19: 1 | B19: 1 | D19: =CORREL(A2:A1501,B2:B1501) -> 0.063095734 | E19: Moderate Positive Relation
A20: 721 | B20: 5
A21: -1 | B21: 2 | D21: Quantity increase than profit also increase
A22: -624 | B22: 5
A23: 95 | B23: 5
A24: 254 | B24: 6
A25: -33 | B25: 4
A26: 2 | B26: 2
A27: 782 | B27: 3
A28: 370 | B28: 8
A29: -266 | B29: 6
A30: -56 | B30: 6
A31: -1 | B31: 3
A32: 202 | B32: 5
A33: 113 | B33: 8
... A1501: 305 | B1501: 5

Sheet Task-5
B2: City | C2: Sum of Amount
B3: Ahmedabad | C3: 14543
B4: Bhopal | C4: 23783
B5: Chandigarh | C5: 21142
B6: Delhi | C6: 22957
B7: Indore | C7: 63680
B8: Kolkata | C8: 14328
B9: Mathura | C9: 28747
B10: Mumbai | C10: 58886
B11: Pune | C11: 43612
B12: Thiruvananthapuram | C12: 13871
B13: Grand Total | C13: 305549

Sheet Task-6
B2: Count of Order ID | C2: Year
B3: Month | C3: 2018 | D3: Grand Total
B4: 1 | C4: 61 | D4: 61 | F4: Highest no of Orders (Jan)
B5: 2 | C5: 54 | D5: 54
B6: 3 | C6: 58 | D6: 58 | F6: Order decreased (Jan to June)
B7: 4 | C7: 44 | D7: 44 | F7: Order stable (June to Sept)
B8: 5 | C8: 31 | D8: 31 | F8: Order increase (Oct to Dec)
B9: 6 | C9: 30 | D9: 30 | F9: Lowest no of order (june)
B10: 7 | C10: 31 | D10: 31
B11: 8 | C11: 31 | D11: 31
B12: 9 | C12: 30 | D12: 30 | F12: Lowest no of order (Aug)
B13: 10 | C13: 43 | D13: 43
B14: 11 | C14: 46 | D14: 46
B15: 12 | C15: 41 | D15: 41
B16: Grand Total | C16: 500 | D16: 500

Sheet Task-7
B2: Sub-Category | C2: Count of Order ID
B3: Bookcases | C3: 79
B4: Electronic Games | C4: 79
B5: Hankerchief | C5: 197
B6: Phones | C6: 83
B7: Saree | C7: 211
B8: Stole | C8: 192
B9: Grand Total | C9: 841

Sheet Task-8
B2: State | C2: Average of Profit
B3: Andhra Pradesh | C3: -6.6666667
B4: Bihar | C4: 28.822581
B5: Delhi | C5: 25.763158
B6: Goa | C6: 8.1395349
B7: Gujarat | C7: 34.494253
B8: Haryana | C8: 50.961538
B9: Himachal Pradesh | C9: 57.310345
B10: Jammu and Kashmir | C10: 4.244898
B11: Karnataka | C11: 8.98
B12: Kerala | C12: 54.111111
B13: Madhya Pradesh | C13: 23.509554
B14: Maharashtra | C14: 23.287625
... B18: Sikkim | C18: 16.708333
B19: Tamil Nadu | C19: 104.08 | E19: Highlighted Low Profit average States
B20: Uttar Pradesh | C20: 38.597701
B21: West Bengal | C21: 32.920635 | E21: Maintain product Quality and Price
B22: Grand Total | C22: 24.642

Sheet Task-9
A1: Amount | B1: Quantity
A2: 1096 | B2: 7 | D2: Correlation Coefficent | G2: =CORREL(A1:A1501,B1:B1501) -> 0.35248611
A3: 5729 | B3: 14
A4: 2927 | B4: 8 | D4: Moderate Positve Correlation
A5: 2847 | B5: 8
A6: 2617 | B6: 4
A7: 2244 | B7: 4
A8: 275 | B8: 4
A9: 387 | B9: 5
A10: 50 | B10: 2
A11: 135 | B11: 5
A12: 231 | B12: 9
A13: 2125 | B13: 6
A14: 3873 | B14: 6
A15: 729 | B15: 5
A16: 2188 | B16: 5
... A1501: 4363 | B1501: 5

Sheet Task-10
B2: PaymentMode | C2: Average of Amount
B3: EMI | C3: 649.00833
B4: Credit Card | C4: 533.32515
B5: Debit Card | C5: 243.24752
B6: COD | C6: 226.87281
B7: UPI | C7: 207.37462
B8: Grand Total | C8: 291.84733
